Workbook

Sheet MR-AR
B1: Coresphere100 Technologies Pvt. Ltd.
B2: Monthly Recurring Revenue
B3: From Apr 25 to Oct 25
B5: Particulars | C5: For the month ended | D5: For the month ended | E5: For the month ended | F5: For the month ended | G5: For the month ended | H5: For the month ended | I5: For the month ended
C6: 45748 | D6: 45778 | E6: 45809 | F6: 45839 | G6: 45870 | H6: 45901 | I6: 45931
B7: Total monthly revenue from B2B subscribers excluding GST (A) | C7: =SUM(C9:C47) -> 1741620.9 | D7: =SUM(D9:D47) -> 2163257.6 | E7: =SUM(E9:E47) -> 2564306.8 | F7: =SUM(F9:F47) -> 3134923.8 | G7: =SUM(G9:G47) -> 3859051.3 | H7: =SUM(H9:H47) -> 4595146.1 | I7: =SUM(I9:I47) -> 5204678.9
B9: Annual Subscription
B10: Annual- Half Yearly Payment | C10: =SUMIF(Pivot!$A$2:$A$42,'MR-AR'!B10,Pivot!$B$2:$B$42)/118% -> 51835.311 | D10: =SUMIF(Pivot!$A$2:$A$42,'MR-AR'!B10,Pivot!$C$2:$C$42)/118% -> 294835.31 | E10: =SUMIF(Pivot!$A$2:$A$42,'MR-AR'!B10,Pivot!$D$2:$D$42)/118% -> 294835.31 | F10: =SUMIF(Pivot!$A$2:$A$42,'MR-AR'!B10,Pivot!$E$2:$E$42)/118% -> 316751.98 | G10: =SUMIF(Pivot!$A$2:$A$42,'MR-AR'!B10,Pivot!$F$2:$F$42)/118% -> 981618.64 | H10: =SUMIF(Pivot!$A$2:$A$42,'MR-AR'!B10,Pivot!$G$2:$G$42)/118% -> 1024702 | I10: =SUMIF(Pivot!$A$2:$A$42,'MR-AR'!B10,Pivot!$H$2:$H$42)/118% -> 1214135.3
B11: Annual subscription, Quarterly upfront | C11: =SUMIF(Pivot!$A$2:$A$42,'MR-AR'!B11,Pivot!$B$2:$B$42)/118% -> 48276.836 | D11: =SUMIF(Pivot!$A$2:$A$42,'MR-AR'!B11,Pivot!$C$2:$C$42)/118% -> 48276.836 | E11: =SUMIF(Pivot!$A$2:$A$42,'MR-AR'!B11,Pivot!$D$2:$D$42)/118% -> 96276.836 | F11: =SUMIF(Pivot!$A$2:$A$42,'MR-AR'!B11,Pivot!$E$2:$E$42)/118% -> 180776.84 | G11: =SUMIF(Pivot!$A$2:$A$42,'MR-AR'!B11,Pivot!$F$2:$F$42)/118% -> 355799.44 | H11: =SUMIF(Pivot!$A$2:$A$42,'MR-AR'!B11,Pivot!$G$2:$G$42)/118% -> 446418.08 | I11: =SUMIF(Pivot!$A$2:$A$42,'MR-AR'!B11,Pivot!$H$2:$H$42)/118% -> 511638.42
B12: Annual Upfront | C12: =SUMIF(Pivot!$A$2:$A$42,'MR-AR'!B12,Pivot!$B$2:$B$42)/118% -> 653322.31 | D12: =SUMIF(Pivot!$A$2:$A$42,'MR-AR'!B12,Pivot!$C$2:$C$42)/118% -> 768915.25 | E12: =SUMIF(Pivot!$A$2:$A$42,'MR-AR'!B12,Pivot!$D$2:$D$42)/118% -> 1006485 | F12: =SUMIF(Pivot!$A$2:$A$42,'MR-AR'!B12,Pivot!$E$2:$E$42)/118% -> 1447016.8 | G12: =SUMIF(Pivot!$A$2:$A$42,'MR-AR'!B12,Pivot!$F$2:$F$42)/118% -> 1673643.1 | H12: =SUMIF(Pivot!$A$2:$A$42,'MR-AR'!B12,Pivot!$G$2:$G$42)/118% -> 1970881.1 | I12: =SUMIF(Pivot!$A$2:$A$42,'MR-AR'!B12,Pivot!$H$2:$H$42)/118% -> 2048228.6
B13: Annual-Monthly | C13: =SUMIF(Pivot!$A$2:$A$42,'MR-AR'!B13,Pivot!$B$2:$B$42)/118% -> 69033.051 | D13: =SUMIF(Pivot!$A$2:$A$42,'MR-AR'!B13,Pivot!$C$2:$C$42)/118% -> 78199.718 | E13: =SUMIF(Pivot!$A$2:$A$42,'MR-AR'!B13,Pivot!$D$2:$D$42)/118% -> 91674.294 | F13: =SUMIF(Pivot!$A$2:$A$42,'MR-AR'!B13,Pivot!$E$2:$E$42)/118% -> 157840.4 | G13: =SUMIF(Pivot!$A$2:$A$42,'MR-AR'!B13,Pivot!$F$2:$F$42)/118% -> 157840.4 | H13: =SUMIF(Pivot!$A$2:$A$42,'MR-AR'!B13,Pivot!$G$2:$G$42)/118% -> 222484.46 | I13: =SUMIF(Pivot!$A$2:$A$42,'MR-AR'!B13,Pivot!$H$2:$H$42)/118% -> 322755.65
B14: 2 Year- Upfront | C14: =SUMIF(Pivot!$A$2:$A$42,'MR-AR'!B14,Pivot!$B$2:$B$42)/118% -> 0 | D14: =SUMIF(Pivot!$A$2:$A$42,'MR-AR'!B14,Pivot!$C$2:$C$42)/118% -> 0 | E14: =SUMIF(Pivot!$A$2:$A$42,'MR-AR'!B14,Pivot!$D$2:$D$42)/118% -> 0 | F14: =SUMIF(Pivot!$A$2:$A$42,'MR-AR'!B14,Pivot!$E$2:$E$42)/118% -> 4021.7542 | G14: =SUMIF(Pivot!$A$2:$A$42,'MR-AR'!B14,Pivot!$F$2:$F$42)/118% -> 4021.7542 | H14: =SUMIF(Pivot!$A$2:$A$42,'MR-AR'!B14,Pivot!$G$2:$G$42)/118% -> 4021.7542 | I14: =SUMIF(Pivot!$A$2:$A$42,'MR-AR'!B14,Pivot!$H$2:$H$42)/118% -> 4021.7542
D15: =SUMIF(Pivot!$A$2:$A$42,'MR-AR'!B15,Pivot!$C$2:$C$42)/118% -> 0 | E15: =SUMIF(Pivot!$A$2:$A$42,'MR-AR'!B15,Pivot!$D$2:$D$42)/118% -> 0 | F15: =SUMIF(Pivot!$A$2:$A$42,'MR-AR'!B15,Pivot!$E$2:$E$42)/118% -> 0 | G15: =SUMIF(Pivot!$A$2:$A$42,'MR-AR'!B15,Pivot!$F$2:$F$42)/118% -> 0 | H15: =SUMIF(Pivot!$A$2:$A$42,'MR-AR'!B15,Pivot!$G$2:$G$42)/118% -> 0 | I15: =SUMIF(Pivot!$A$2:$A$42,'MR-AR'!B15,Pivot!$H$2:$H$42)/118% -> 0
B16: Other Than Annual Subscriptions | D16: =SUMIF(Pivot!$A$2:$A$42,'MR-AR'!B16,Pivot!$C$2:$C$42)/118% -> 0 | E16: =SUMIF(Pivot!$A$2:$A$42,'MR-AR'!B16,Pivot!$D$2:$D$42)/118% -> 0 | F16: =SUMIF(Pivot!$A$2:$A$42,'MR-AR'!B16,Pivot!$E$2:$E$42)/118% -> 0 | G16: =SUMIF(Pivot!$A$2:$A$42,'MR-AR'!B16,Pivot!$F$2:$F$42)/118% -> 0 | H16: =SUMIF(Pivot!$A$2:$A$42,'MR-AR'!B16,Pivot!$G$2:$G$42)/118% -> 0 | I16: =SUMIF(Pivot!$A$2:$A$42,'MR-AR'!B16,Pivot!$H$2:$H$42)/118% -> 0
B17: 10 -Days -Upfront | C17: =SUMIF(Pivot!$A$2:$A$42,'MR-AR'!B17,Pivot!$B$2:$B$42)/118% -> 0 | D17: =SUMIF(Pivot!$A$2:$A$42,'MR-AR'!B17,Pivot!$C$2:$C$42)/118% -> 0 | E17: =SUMIF(Pivot!$A$2:$A$42,'MR-AR'!B17,Pivot!$D$2:$D$42)/118% -> 0 | F17: =SUMIF(Pivot!$A$2:$A$42,'MR-AR'!B17,Pivot!$E$2:$E$42)/118% -> 8000 | G17: =SUMIF(Pivot!$A$2:$A$42,'MR-AR'!B17,Pivot!$F$2:$F$42)/118% -> 0 | H17: =SUMIF(Pivot!$A$2:$A$42,'MR-AR'!B17,Pivot!$G$2:$G$42)/118% -> 0 | I17: =SUMIF(Pivot!$A$2:$A$42,'MR-AR'!B17,Pivot!$H$2:$H$42)/118% -> 0
B18: 12 -Days -Upfront | C18: =SUMIF(Pivot!$A$2:$A$42,'MR-AR'!B18,Pivot!$B$2:$B$42)/118% -> 0 | D18: =SUMIF(Pivot!$A$2:$A$42,'MR-AR'!B18,Pivot!$C$2:$C$42)/118% -> 0 | E18: =SUMIF(Pivot!$A$2:$A$42,'MR-AR'!B18,Pivot!$D$2:$D$42)/118% -> 0 | F18: =SUMIF(Pivot!$A$2:$A$42,'MR-AR'!B18,Pivot!$E$2:$E$42)/118% -> 0 | G18: =SUMIF(Pivot!$A$2:$A$42,'MR-AR'!B18,Pivot!$F$2:$F$42)/118% -> 3483.8983 | H18: =SUMIF(Pivot!$A$2:$A$42,'MR-AR'!B18,Pivot!$G$2:$G$42)/118% -> 0 | I18: =SUMIF(Pivot!$A$2:$A$42,'MR-AR'!B18,Pivot!$H$2:$H$42)/118% -> 0
B19: 15 -Days -Upfront | C19: =SUMIF(Pivot!$A$2:$A$42,'MR-AR'!B19,Pivot!$B$2:$B$42)/118% -> 0 | D19: =SUMIF(Pivot!$A$2:$A$42,'MR-AR'!B19,Pivot!$C$2:$C$42)/118% -> 0 | E19: =SUMIF(Pivot!$A$2:$A$42,'MR-AR'!B19,Pivot!$D$2:$D$42)/118% -> 0 | F19: =SUMIF(Pivot!$A$2:$A$42,'MR-AR'!B19,Pivot!$E$2:$E$42)/118% -> 0 | G19: =SUMIF(Pivot!$A$2:$A$42,'MR-AR'!B19,Pivot!$F$2:$F$42)/118% -> 0 | H19: =SUMIF(Pivot!$A$2:$A$42,'MR-AR'!B19,Pivot!$G$2:$G$42)/118% -> 4000 | I19: =SUMIF(Pivot!$A$2:$A$42,'MR-AR'!B19,Pivot!$H$2:$H$42)/118% -> 0
B20: 13 month-Upfront | C20: =SUMIF(Pivot!$A$2:$A$42,'MR-AR'!B20,Pivot!$B$2:$B$42)/118% -> 0 | D20: =SUMIF(Pivot!$A$2:$A$42,'MR-AR'!B20,Pivot!$C$2:$C$42)/118% -> 0 | E20: =SUMIF(Pivot!$A$2:$A$42,'MR-AR'!B20,Pivot!$D$2:$D$42)/118% -> 0 | F20: =SUMIF(Pivot!$A$2:$A$42,'MR-AR'!B20,Pivot!$E$2:$E$42)/118% -> 0 | G20: =SUMIF(Pivot!$A$2:$A$42,'MR-AR'!B20,Pivot!$F$2:$F$42)/118% -> 0 | H20: =SUMIF(Pivot!$A$2:$A$42,'MR-AR'!B20,Pivot!$G$2:$G$42)/118% -> 0 | I20: =SUMIF(Pivot!$A$2:$A$42,'MR-AR'!B20,Pivot!$H$2:$H$42)/118% -> 0
B21: 19 -Days -Upfront | C21: =SUMIF(Pivot!$A$2:$A$42,'MR-AR'!B21,Pivot!$B$2:$B$42)/118% -> 0 | D21: =SUMIF(Pivot!$A$2:$A$42,'MR-AR'!B21,Pivot!$C$2:$C$42)/118% -> 0 | E21: =SUMIF(Pivot!$A$2:$A$42,'MR-AR'!B21,Pivot!$D$2:$D$42)/118% -> 0 | F21: =SUMIF(Pivot!$A$2:$A$42,'MR-AR'!B21,Pivot!$E$2:$E$42)/118% -> 34592.52 | G21: =SUMIF(Pivot!$A$2:$A$42,'MR-AR'!B21,Pivot!$F$2:$F$42)/118% -> 11032.203 | H21: =SUMIF(Pivot!$A$2:$A$42,'MR-AR'!B21,Pivot!$G$2:$G$42)/118% -> 0 | I21: =SUMIF(Pivot!$A$2:$A$42,'MR-AR'!B21,Pivot!$H$2:$H$42)/118% -> 0
B22: 38 -Days -Upfront | C22: =SUMIF(Pivot!$A$2:$A$42,'MR-AR'!B22,Pivot!$B$2:$B$42)/118% -> 0 | D22: =SUMIF(Pivot!$A$2:$A$42,'MR-AR'!B22,Pivot!$C$2:$C$42)/118% -> 0 | E22: =SUMIF(Pivot!$A$2:$A$42,'MR-AR'!B22,Pivot!$D$2:$D$42)/118% -> 4934.2105 | F22: =SUMIF(Pivot!$A$2:$A$42,'MR-AR'!B22,Pivot!$E$2:$E$42)/118% -> 0 | G22: =SUMIF(Pivot!$A$2:$A$42,'MR-AR'!B22,Pivot!$F$2:$F$42)/118% -> 0 | H22: =SUMIF(Pivot!$A$2:$A$42,'MR-AR'!B22,Pivot!$G$2:$G$42)/118% -> 0 | I22: =SUMIF(Pivot!$A$2:$A$42,'MR-AR'!B22,Pivot!$H$2:$H$42)/118% -> 0
B23: 1 month-Upfront | C23: =SUMIF(Pivot!$A$2:$A$42,'MR-AR'!B23,Pivot!$B$2:$B$42)/118% -> 185711.86 | D23: =SUMIF(Pivot!$A$2:$A$42,'MR-AR'!B23,Pivot!$C$2:$C$42)/118% -> 231211.87 | E23: =SUMIF(Pivot!$A$2:$A$42,'MR-AR'!B23,Pivot!$D$2:$D$42)/118% -> 310949.15 | F23: =SUMIF(Pivot!$A$2:$A$42,'MR-AR'!B23,Pivot!$E$2:$E$42)/118% -> 445211.86 | G23: =SUMIF(Pivot!$A$2:$A$42,'MR-AR'!B23,Pivot!$F$2:$F$42)/118% -> 57474.576 | H23: =SUMIF(Pivot!$A$2:$A$42,'MR-AR'!B23,Pivot!$G$2:$G$42)/118% -> 159146.16 | I23: =SUMIF(Pivot!$A$2:$A$42,'MR-AR'!B23,Pivot!$H$2:$H$42)/118% -> 203241.14
B24: 2 months subscription, Monthly | C24: =SUMIF(Pivot!$A$2:$A$42,'MR-AR'!B24,Pivot!$B$2:$B$42)/118% -> 40000 | D24: =SUMIF(Pivot!$A$2:$A$42,'MR-AR'!B24,Pivot!$C$2:$C$42)/118% -> 30000 | E24: =SUMIF(Pivot!$A$2:$A$42,'MR-AR'!B24,Pivot!$D$2:$D$42)/118% -> 9000 | F24: =SUMIF(Pivot!$A$2:$A$42,'MR-AR'!B24,Pivot!$E$2:$E$42)/118% -> 9000 | G24: =SUMIF(Pivot!$A$2:$A$42,'MR-AR'!B24,Pivot!$F$2:$F$42)/118% -> 42916 | H24: =SUMIF(Pivot!$A$2:$A$42,'MR-AR'!B24,Pivot!$G$2:$G$42)/118% -> 42916 | I24: =SUMIF(Pivot!$A$2:$A$42,'MR-AR'!B24,Pivot!$H$2:$H$42)/118% -> 0
B25: 2 months- Upfront | C25: =SUMIF(Pivot!$A$2:$A$42,'MR-AR'!B25,Pivot!$B$2:$B$42)/118% -> 89000 | D25: =SUMIF(Pivot!$A$2:$A$42,'MR-AR'!B25,Pivot!$C$2:$C$42)/118% -> 125500 | E25: =SUMIF(Pivot!$A$2:$A$42,'MR-AR'!B25,Pivot!$D$2:$D$42)/118% -> 71500 | F25: =SUMIF(Pivot!$A$2:$A$42,'MR-AR'!B25,Pivot!$E$2:$E$42)/118% -> 10000 | G25: =SUMIF(Pivot!$A$2:$A$42,'MR-AR'!B25,Pivot!$F$2:$F$42)/118% -> 10000 | H25: =SUMIF(Pivot!$A$2:$A$42,'MR-AR'!B25,Pivot!$G$2:$G$42)/118% -> 0 | I25: =SUMIF(Pivot!$A$2:$A$42,'MR-AR'!B25,Pivot!$H$2:$H$42)/118% -> 0
B26: 2 month & 13 Days-Upfront | C26: =SUMIF(Pivot!$A$2:$A$42,'MR-AR'!B26,Pivot!$B$2:$B$42)/118% -> 0 | D26: =SUMIF(Pivot!$A$2:$A$42,'MR-AR'!B26,Pivot!$C$2:$C$42)/118% -> 0 | E26: =SUMIF(Pivot!$A$2:$A$42,'MR-AR'!B26,Pivot!$D$2:$D$42)/118% -> 0 | F26: =SUMIF(Pivot!$A$2:$A$42,'MR-AR'!B26,Pivot!$E$2:$E$42)/118% -> 0 | G26: =SUMIF(Pivot!$A$2:$A$42,'MR-AR'!B26,Pivot!$F$2:$F$42)/118% -> 0 | H26: =SUMIF(Pivot!$A$2:$A$42,'MR-AR'!B26,Pivot!$G$2:$G$42)/118% -> 0 | I26: =SUMIF(Pivot!$A$2:$A$42,'MR-AR'!B26,Pivot!$H$2:$H$42)/118% -> 7632.8957
B27: 3 months subscription, Monthly | C27: =SUMIF(Pivot!$A$2:$A$42,'MR-AR'!B27,Pivot!$B$2:$B$42)/118% -> 150000 | D27: =SUMIF(Pivot!$A$2:$A$42,'MR-AR'!B27,Pivot!$C$2:$C$42)/118% -> 150000 | E27: =SUMIF(Pivot!$A$2:$A$42,'MR-AR'!B27,Pivot!$D$2:$D$42)/118% -> 150000 | F27: =SUMIF(Pivot!$A$2:$A$42,'MR-AR'!B27,Pivot!$E$2:$E$42)/118% -> 0 | G27: =SUMIF(Pivot!$A$2:$A$42,'MR-AR'!B27,Pivot!$F$2:$F$42)/118% -> 0 | H27: =SUMIF(Pivot!$A$2:$A$42,'MR-AR'!B27,Pivot!$G$2:$G$42)/118% -> 0 | I27: =SUMIF(Pivot!$A$2:$A$42,'MR-AR'!B27,Pivot!$H$2:$H$42)/118% -> 0
B28: 3 months subscription, upfront | C28: =SUMIF(Pivot!$A$2:$A$42,'MR-AR'!B28,Pivot!$B$2:$B$42)/118% -> 175445.48 | D28: =SUMIF(Pivot!$A$2:$A$42,'MR-AR'!B28,Pivot!$C$2:$C$42)/118% -> 137522.6 | E28: =SUMIF(Pivot!$A$2:$A$42,'MR-AR'!B28,Pivot!$D$2:$D$42)/118% -> 118022.6 | F28: =SUMIF(Pivot!$A$2:$A$42,'MR-AR'!B28,Pivot!$E$2:$E$42)/118% -> 40022.599 | G28: =SUMIF(Pivot!$A$2:$A$42,'MR-AR'!B28,Pivot!$F$2:$F$42)/118% -> 38666.667 | H28: =SUMIF(Pivot!$A$2:$A$42,'MR-AR'!B28,Pivot!$G$2:$G$42)/118% -> 20666.667 | I28: =SUMIF(Pivot!$A$2:$A$42,'MR-AR'!B28,Pivot!$H$2:$H$42)/118% -> 20666.667
... B46: 1year & 6 months - Half Yearly Payment | C46: =SUMIF(Pivot!$A$2:$A$42,'MR-AR'!B46,Pivot!$B$2:$B$42)/118% -> 0 | D46: =SUMIF(Pivot!$A$2:$A$42,'MR-AR'!B46,Pivot!$C$2:$C$42)/118% -> 0 | E46: =SUMIF(Pivot!$A$2:$A$42,'MR-AR'!B46,Pivot!$D$2:$D$42)/118% -> 0 | F46: =SUMIF(Pivot!$A$2:$A$42,'MR-AR'!B46,Pivot!$E$2:$E$42)/118% -> 0 | G46: =SUMIF(Pivot!$A$2:$A$42,'MR-AR'!B46,Pivot!$F$2:$F$42)/118% -> 0 | H46: =SUMIF(Pivot!$A$2:$A$42,'MR-AR'!B46,Pivot!$G$2:$G$42)/118% -> 0 | I46: =SUMIF(Pivot!$A$2:$A$42,'MR-AR'!B46,Pivot!$H$2:$H$42)/118% -> 0
B48: Total monthly revenue from B2C subscribers (B) | C48: =Invoices!M13 -> 42252 | D48: =Invoices!M14 -> 24128 | E48: =Invoices!M15 -> 24554.28 | F48: =Invoices!M16 -> 19474 | G48: =Invoices!M17 -> 18627 | H48: =Invoices!M18 -> 14394.92 | I48: =Invoices!M20 -> 13549.16
B50: Total monthly revenue from B2B and B2C C=A+B | C50: =C7+C48 -> 1783872.9 | D50: =D7+D48 -> 2187385.6 | E50: =E7+E48 -> 2588861.1 | F50: =F7+F48 -> 3154397.8 | G50: =G7+G48 -> 3877678.3 | H50: =H7+H48 -> 4609541 | I50: =I7+I48 -> 5218228.1
B52: Monthly Recurring revenue (excluding one time and others)-B2B | C52: =C50-C48 -> 1741620.9 | D52: =D50-D48 -> 2163257.6 | E52: =E50-E48 -> 2564306.8 | F52: =F50-F48 -> 3134923.8 | G52: =G50-G48 -> 3859051.3 | H52: =H50-H48 -> 4595146.1 | I52: =I50-I48 -> 5204678.9
B54: No. of active subscribers-B2B | C54: ='Customer churnout'!G6 -> 117 | D54: ='Customer churnout'!G9 -> 143 | E54: ='Customer churnout'!H9 -> 158 | F54: ='Customer churnout'!I9 -> 195 | G54: ='Customer churnout'!J9 -> 219 | H54: ='Customer churnout'!K9 -> 245 | I54: ='Customer churnout'!L9 -> 288
B56: Monthly recurring revenue per subscriber | C56: =C52/C54 -> 14885.649 | D56: =D52/D54 -> 15127.676 | E56: =E52/E54 -> 16229.79 | F56: =F52/F54 -> 16076.533 | G56: =G52/G54 -> 17621.239 | H56: =H52/H54 -> 18755.698 | I56: =I52/I54 -> 18071.802
B58: Total Annual Recurring revenue (excluding one time and others)-B2B | C58: =C52*12 -> 20899451 | D58: =D52*12 -> 25959092 | E58: =E52*12 -> 30771682 | F58: =F52*12 -> 37619086 | G58: =G52*12 -> 46308616 | H58: =H52*12 -> 55141753 | I58: =I52*12 -> 62456147

Sheet MR Accrual
B1: Coresphere100 Technologies Pvt. Ltd.
B2: Monthly revenue (Accrual)
F3: Amount in INR
B4: Particulars | C4: For the month ended | D4: For the month ended | E4: For the month ended | F4: For the month ended | G4: For the month ended | H4: For the month ended | I4: For the month ended | J4: For the month ended
C5: 45748 | D5: 45748 | E5: 45778 | F5: 45809 | G5: 45839 | H5: 45870 | I5: 45901 | J5: 45931 | K5: Total
B6: Monthly Revenue from B2B subscribers (A) | D6: =SUM(D9:D45) -> 1491256.2 | E6: =SUM(E9:E45) -> 2038366.3 | F6: =SUM(F9:F45) -> 2336604.3 | G6: =SUM(G9:G45) -> 2883930.9 | H6: =SUM(H9:H45) -> 3628578.2 | I6: =SUM(I9:I45) -> 4447689.3 | J6: =SUM(J9:J45) -> 5065908.8 | K6: =SUM(K9:K45) -> 21892334
B8: Annual Subscription
B9: Annual- Half Yearly Payment | D9: =SUMIF(Pivot!$A$45:$A$84,B9,Pivot!$B$45:$B$84)/118% -> 45591.266 | E9: =SUMIF(Pivot!$A$45:$A$84,B9,Pivot!$C$45:$C$84)/118% -> 68463.254 | F9: =SUMIF(Pivot!$A$45:$A$84,B9,Pivot!$D$45:$D$84)/118% -> 290463.33 | G9: =SUMIF(Pivot!$A$45:$A$84,B9,Pivot!$E$45:$E$84)/118% -> 316997.5 | H9: =SUMIF(Pivot!$A$45:$A$84,B9,Pivot!$F$45:$F$84)/118% -> 673159.02 | I9: =SUMIF(Pivot!$A$45:$A$84,B9,Pivot!$G$45:$G$84)/118% -> 1000802.2 | J9: =SUMIF(Pivot!$A$45:$H$84,B9,Pivot!$H$45:$H$84)/118% -> 1177971.3 | K9: =SUM(D9:J9) -> 3573447.9
B10: Annual subscription, Quarterly upfront | D10: =SUMIF(Pivot!$A$45:$A$84,B10,Pivot!$B$45:$B$84)/118% -> 47587.42 | E10: =SUMIF(Pivot!$A$45:$A$84,B10,Pivot!$C$45:$C$84)/118% -> 49173.667 | F10: =SUMIF(Pivot!$A$45:$A$84,B10,Pivot!$D$45:$D$84)/118% -> 63038.25 | G10: =SUMIF(Pivot!$A$45:$A$84,B10,Pivot!$E$45:$E$84)/118% -> 172929.77 | H10: =SUMIF(Pivot!$A$45:$A$84,B10,Pivot!$F$45:$F$84)/118% -> 344434.76 | I10: =SUMIF(Pivot!$A$45:$A$84,B10,Pivot!$G$45:$G$84)/118% -> 420350.41 | J10: =SUMIF(Pivot!$A$45:$H$84,B10,Pivot!$H$45:$H$84)/118% -> 501192.13 | K10: =SUM(D10:J10) -> 1598706.4
B11: Annual Upfront | D11: =SUMIF(Pivot!$A$45:$A$84,B11,Pivot!$B$45:$B$84)/118% -> 565804 | E11: =SUMIF(Pivot!$A$45:$A$84,B11,Pivot!$C$45:$C$84)/118% -> 719682.25 | F11: =SUMIF(Pivot!$A$45:$A$84,B11,Pivot!$D$45:$D$84)/118% -> 932783.84 | G11: =SUMIF(Pivot!$A$45:$A$84,B11,Pivot!$E$45:$E$84)/118% -> 1242097.4 | H11: =SUMIF(Pivot!$A$45:$A$84,B11,Pivot!$F$45:$F$84)/118% -> 1589492.6 | I11: =SUMIF(Pivot!$A$45:$A$84,B11,Pivot!$G$45:$G$84)/118% -> 1866858.4 | J11: =SUMIF(Pivot!$A$45:$H$84,B11,Pivot!$H$45:$H$84)/118% -> 2048295.9 | K11: =SUM(D11:J11) -> 8965014.4
B12: Annual-Monthly | D12: =SUMIF(Pivot!$A$45:$A$84,B12,Pivot!$B$45:$B$84)/118% -> 47801.532 | E12: =SUMIF(Pivot!$A$45:$A$84,B12,Pivot!$C$45:$C$84)/118% -> 208651.43 | F12: =SUMIF(Pivot!$A$45:$A$84,B12,Pivot!$D$45:$D$84)/118% -> 85456.512 | G12: =SUMIF(Pivot!$A$45:$A$84,B12,Pivot!$E$45:$E$84)/118% -> 123035.95 | H12: =SUMIF(Pivot!$A$45:$A$84,B12,Pivot!$F$45:$F$84)/118% -> 161676.67 | I12: =SUMIF(Pivot!$A$45:$A$84,B12,Pivot!$G$45:$G$84)/118% -> 192829.62 | J12: =SUMIF(Pivot!$A$45:$H$84,B12,Pivot!$H$45:$H$84)/118% -> 281866.93 | K12: =SUM(D12:J12) -> 1101318.6
B13: 2 Year- Upfront | D13: =SUMIF(Pivot!$A$45:$A$84,B13,Pivot!$B$45:$B$84)/118% -> 0 | E13: =SUMIF(Pivot!$A$45:$A$84,B13,Pivot!$C$45:$C$84)/118% -> 0 | F13: =SUMIF(Pivot!$A$45:$A$84,B13,Pivot!$D$45:$D$84)/118% -> 0 | G13: =SUMIF(Pivot!$A$45:$A$84,B13,Pivot!$E$45:$E$84)/118% -> 1189.9985 | H13: =SUMIF(Pivot!$A$45:$A$84,B13,Pivot!$F$45:$F$84)/118% -> 4098.8838 | I13: =SUMIF(Pivot!$A$45:$A$84,B13,Pivot!$G$45:$G$84)/118% -> 3966.6617 | J13: =SUMIF(Pivot!$A$45:$H$84,B13,Pivot!$H$45:$H$84)/118% -> 4098.8838 | K13: =SUM(D13:J13) -> 13354.428
D14: =SUMIF(Pivot!$A$45:$A$84,B14,Pivot!$B$45:$B$84)/118% -> 0 | E14: =SUMIF(Pivot!$A$45:$A$84,B14,Pivot!$C$45:$C$84)/118% -> 0 | F14: =SUMIF(Pivot!$A$45:$A$84,B14,Pivot!$D$45:$D$84)/118% -> 0 | G14: =SUMIF(Pivot!$A$45:$A$84,B14,Pivot!$E$45:$E$84)/118% -> 0 | H14: =SUMIF(Pivot!$A$45:$A$84,B14,Pivot!$F$45:$F$84)/118% -> 0 | I14: =SUMIF(Pivot!$A$45:$A$84,B14,Pivot!$G$45:$G$84)/118% -> 0 | J14: =SUMIF(Pivot!$A$45:$H$84,B14,Pivot!$H$45:$H$84)/118% -> 0 | K14: =SUM(D14:J14) -> 0
B15: Other Than Annual Subscriptions | D15: =SUMIF(Pivot!$A$45:$A$84,B15,Pivot!$B$45:$B$84)/118% -> 0 | E15: =SUMIF(Pivot!$A$45:$A$84,B15,Pivot!$C$45:$C$84)/118% -> 0 | F15: =SUMIF(Pivot!$A$45:$A$84,B15,Pivot!$D$45:$D$84)/118% -> 0 | G15: =SUMIF(Pivot!$A$45:$A$84,B15,Pivot!$E$45:$E$84)/118% -> 0 | H15: =SUMIF(Pivot!$A$45:$A$84,B15,Pivot!$F$45:$F$84)/118% -> 0 | I15: =SUMIF(Pivot!$A$45:$A$84,B15,Pivot!$G$45:$G$84)/118% -> 0 | J15: =SUMIF(Pivot!$A$45:$H$84,B15,Pivot!$H$45:$H$84)/118% -> 0 | K15: =SUM(D15:J15) -> 0
B16: 10 -Days -Upfront | D16: =SUMIF(Pivot!$A$45:$A$84,B16,Pivot!$B$45:$B$84)/118% -> 0 | E16: =SUMIF(Pivot!$A$45:$A$84,B16,Pivot!$C$45:$C$84)/118% -> 0 | F16: =SUMIF(Pivot!$A$45:$A$84,B16,Pivot!$D$45:$D$84)/118% -> 0 | G16: =SUMIF(Pivot!$A$45:$A$84,B16,Pivot!$E$45:$E$84)/118% -> 8000 | H16: =SUMIF(Pivot!$A$45:$A$84,B16,Pivot!$F$45:$F$84)/118% -> 0 | I16: =SUMIF(Pivot!$A$45:$A$84,B16,Pivot!$G$45:$G$84)/118% -> 0 | J16: =SUMIF(Pivot!$A$45:$H$84,B16,Pivot!$H$45:$H$84)/118% -> 0 | K16: =SUM(D16:J16) -> 8000
B17: 12 -Days -Upfront | D17: =SUMIF(Pivot!$A$45:$A$84,B17,Pivot!$B$45:$B$84)/118% -> 0 | E17: =SUMIF(Pivot!$A$45:$A$84,B17,Pivot!$C$45:$C$84)/118% -> 0 | F17: =SUMIF(Pivot!$A$45:$A$84,B17,Pivot!$D$45:$D$84)/118% -> 0 | G17: =SUMIF(Pivot!$A$45:$A$84,B17,Pivot!$E$45:$E$84)/118% -> 0 | H17: =SUMIF(Pivot!$A$45:$A$84,B17,Pivot!$F$45:$F$84)/118% -> 3483.8983 | I17: =SUMIF(Pivot!$A$45:$A$84,B17,Pivot!$G$45:$G$84)/118% -> 0 | J17: =SUMIF(Pivot!$A$45:$H$84,B17,Pivot!$H$45:$H$84)/118% -> 0 | K17: =SUM(D17:J17) -> 3483.8983
B18: 15 -Days -Upfront | D18: =SUMIF(Pivot!$A$45:$A$84,B18,Pivot!$B$45:$B$84)/118% -> 0 | E18: =SUMIF(Pivot!$A$45:$A$84,B18,Pivot!$C$45:$C$84)/118% -> 0 | F18: =SUMIF(Pivot!$A$45:$A$84,B18,Pivot!$D$45:$D$84)/118% -> 0 | G18: =SUMIF(Pivot!$A$45:$A$84,B18,Pivot!$E$45:$E$84)/118% -> 0 | H18: =SUMIF(Pivot!$A$45:$A$84,B18,Pivot!$F$45:$F$84)/118% -> 0 | I18: =SUMIF(Pivot!$A$45:$A$84,B18,Pivot!$G$45:$G$84)/118% -> 4000 | J18: =SUMIF(Pivot!$A$45:$H$84,B18,Pivot!$H$45:$H$84)/118% -> 0 | K18: =SUM(D18:J18) -> 4000
B19: 13 month-Upfront | D19: =SUMIF(Pivot!$A$45:$A$84,B19,Pivot!$B$45:$B$84)/118% -> 0 | E19: =SUMIF(Pivot!$A$45:$A$84,B19,Pivot!$C$45:$C$84)/118% -> 0 | F19: =SUMIF(Pivot!$A$45:$A$84,B19,Pivot!$D$45:$D$84)/118% -> 0 | G19: =SUMIF(Pivot!$A$45:$A$84,B19,Pivot!$E$45:$E$84)/118% -> 0 | H19: =SUMIF(Pivot!$A$45:$A$84,B19,Pivot!$F$45:$F$84)/118% -> 0 | I19: =SUMIF(Pivot!$A$45:$A$84,B19,Pivot!$G$45:$G$84)/118% -> 0 | J19: =SUMIF(Pivot!$A$45:$H$84,B19,Pivot!$H$45:$H$84)/118% -> 0 | K19: =SUM(D19:J19) -> 0
B20: 19 -Days -Upfront | D20: =SUMIF(Pivot!$A$45:$A$84,B20,Pivot!$B$45:$B$84)/118% -> 0 | E20: =SUMIF(Pivot!$A$45:$A$84,B20,Pivot!$C$45:$C$84)/118% -> 0 | F20: =SUMIF(Pivot!$A$45:$A$84,B20,Pivot!$D$45:$D$84)/118% -> 0 | G20: =SUMIF(Pivot!$A$45:$A$84,B20,Pivot!$E$45:$E$84)/118% -> 7687.2267 | H20: =SUMIF(Pivot!$A$45:$A$84,B20,Pivot!$F$45:$F$84)/118% -> 37937.497 | I20: =SUMIF(Pivot!$A$45:$A$84,B20,Pivot!$G$45:$G$84)/118% -> 0 | J20: =SUMIF(Pivot!$A$45:$H$84,B20,Pivot!$H$45:$H$84)/118% -> 0 | K20: =SUM(D20:J20) -> 45624.723
B21: 38 -Days -Upfront | D21: =SUMIF(Pivot!$A$45:$A$84,B21,Pivot!$B$45:$B$84)/118% -> 0 | E21: =SUMIF(Pivot!$A$45:$A$84,B21,Pivot!$C$45:$C$84)/118% -> 0 | F21: =SUMIF(Pivot!$A$45:$A$84,B21,Pivot!$D$45:$D$84)/118% -> 3947.3684 | G21: =SUMIF(Pivot!$A$45:$A$84,B21,Pivot!$E$45:$E$84)/118% -> 2302.6316 | H21: =SUMIF(Pivot!$A$45:$A$84,B21,Pivot!$F$45:$F$84)/118% -> 0 | I21: =SUMIF(Pivot!$A$45:$A$84,B21,Pivot!$G$45:$G$84)/118% -> 0 | J21: =SUMIF(Pivot!$A$45:$H$84,B21,Pivot!$H$45:$H$84)/118% -> 0 | K21: =SUM(D21:J21) -> 6250
B22: 1 month-Upfront | D22: =SUMIF(Pivot!$A$45:$A$84,B22,Pivot!$B$45:$B$84)/118% -> 211039.61 | E22: =SUMIF(Pivot!$A$45:$A$84,B22,Pivot!$C$45:$C$84)/118% -> 251536.22 | F22: =SUMIF(Pivot!$A$45:$A$84,B22,Pivot!$D$45:$D$84)/118% -> 300929.68 | G22: =SUMIF(Pivot!$A$45:$A$84,B22,Pivot!$E$45:$E$84)/118% -> 378916.63 | H22: =SUMIF(Pivot!$A$45:$A$84,B22,Pivot!$F$45:$F$84)/118% -> 189317.77 | I22: =SUMIF(Pivot!$A$45:$A$84,B22,Pivot!$G$45:$G$84)/118% -> 109793.59 | J22: =SUMIF(Pivot!$A$45:$H$84,B22,Pivot!$H$45:$H$84)/118% -> 178266.07 | K22: =SUM(D22:J22) -> 1619799.6
B23: 2 months subscription, Monthly | D23: =SUMIF(Pivot!$A$45:$A$84,B23,Pivot!$B$45:$B$84)/118% -> 39185.616 | E23: =SUMIF(Pivot!$A$45:$A$84,B23,Pivot!$C$45:$C$84)/118% -> 33395.029 | F23: =SUMIF(Pivot!$A$45:$A$84,B23,Pivot!$D$45:$D$84)/118% -> 8852.459 | G23: =SUMIF(Pivot!$A$45:$A$84,B23,Pivot!$E$45:$E$84)/118% -> 9147.541 | H23: =SUMIF(Pivot!$A$45:$A$84,B23,Pivot!$F$45:$F$84)/118% -> 95681.574 | I23: =SUMIF(Pivot!$A$45:$A$84,B23,Pivot!$G$45:$G$84)/118% -> 168849.84 | J23: =SUMIF(Pivot!$A$45:$H$84,B23,Pivot!$H$45:$H$84)/118% -> 78796.59 | K23: =SUM(D23:J23) -> 433908.65
B24: 2 months- Upfront | D24: =SUMIF(Pivot!$A$45:$A$84,B24,Pivot!$B$45:$B$84)/118% -> 64638.815 | E24: =SUMIF(Pivot!$A$45:$A$84,B24,Pivot!$C$45:$C$84)/118% -> 113771.81 | F24: =SUMIF(Pivot!$A$45:$A$84,B24,Pivot!$D$45:$D$84)/118% -> 91831.306 | G24: =SUMIF(Pivot!$A$45:$A$84,B24,Pivot!$E$45:$E$84)/118% -> 42532.258 | H24: =SUMIF(Pivot!$A$45:$A$84,B24,Pivot!$F$45:$F$84)/118% -> 10000 | I24: =SUMIF(Pivot!$A$45:$A$84,B24,Pivot!$G$45:$G$84)/118% -> 6774.1935 | J24: =SUMIF(Pivot!$A$45:$H$84,B24,Pivot!$H$45:$H$84)/118% -> 0 | K24: =SUM(D24:J24) -> 329548.39
B25: 2 month & 13 Days-Upfront | D25: =SUMIF(Pivot!$A$45:$A$84,B25,Pivot!$B$45:$B$84)/118% -> 0 | E25: =SUMIF(Pivot!$A$45:$A$84,B25,Pivot!$C$45:$C$84)/118% -> 0 | F25: =SUMIF(Pivot!$A$45:$A$84,B25,Pivot!$D$45:$D$84)/118% -> 0 | G25: =SUMIF(Pivot!$A$45:$A$84,B25,Pivot!$E$45:$E$84)/118% -> 0 | H25: =SUMIF(Pivot!$A$45:$A$84,B25,Pivot!$F$45:$F$84)/118% -> 0 | I25: =SUMIF(Pivot!$A$45:$A$84,B25,Pivot!$G$45:$G$84)/118% -> 0 | J25: =SUMIF(Pivot!$A$45:$H$84,B25,Pivot!$H$45:$H$84)/118% -> 4350.7505 | K25: =SUM(D25:J25) -> 4350.7505
B26: 3 months subscription, Monthly | D26: =SUMIF(Pivot!$A$45:$A$84,B26,Pivot!$B$45:$B$84)/118% -> 99487.8 | E26: =SUMIF(Pivot!$A$45:$A$84,B26,Pivot!$C$45:$C$84)/118% -> 153296.7 | F26: =SUMIF(Pivot!$A$45:$A$84,B26,Pivot!$D$45:$D$84)/118% -> 148351.65 | G26: =SUMIF(Pivot!$A$45:$A$84,B26,Pivot!$E$45:$E$84)/118% -> 69230.769 | H26: =SUMIF(Pivot!$A$45:$A$84,B26,Pivot!$F$45:$F$84)/118% -> 0 | I26: =SUMIF(Pivot!$A$45:$A$84,B26,Pivot!$G$45:$G$84)/118% -> 0 | J26: =SUMIF(Pivot!$A$45:$H$84,B26,Pivot!$H$45:$H$84)/118% -> 0 | K26: =SUM(D26:J26) -> 470366.92
... B45: 1year & 6 months - Half Yearly Payment | D45: =SUMIF(Pivot!$A$45:$A$84,B45,Pivot!$B$45:$B$84)/118% -> 0 | E45: =SUMIF(Pivot!$A$45:$A$84,B45,Pivot!$C$45:$C$84)/118% -> 0 | F45: =SUMIF(Pivot!$A$45:$A$84,B45,Pivot!$D$45:$D$84)/118% -> 0 | G45: =SUMIF(Pivot!$A$45:$A$84,B45,Pivot!$E$45:$E$84)/118% -> 0 | H45: =SUMIF(Pivot!$A$45:$A$84,B45,Pivot!$F$45:$F$84)/118% -> 0 | I45: =SUMIF(Pivot!$A$45:$A$84,B45,Pivot!$G$45:$G$84)/118% -> 0 | J45: =SUMIF(Pivot!$A$45:$H$84,B45,Pivot!$H$45:$H$84)/118% -> 0 | K45: =SUM(D45:J45) -> 0
B47: Monthly Revenue from B2C subscribers (B) | D47: ='MR-AR'!C48 -> 42252 | E47: ='MR-AR'!D48 -> 24128 | F47: ='MR-AR'!E48 -> 24554.28 | G47: =Invoices!M16 -> 19474 | H47: =Invoices!M17 -> 18627 | I47: =Invoices!M18 -> 14394.92 | J47: =Invoices!M20 -> 13549.16 | K47: =SUM(D47:J47) -> 156979.36
B49: Monthly Revenue from B2B and B2C C=A+B | D49: =D6+D47 -> 1533508.2 | E49: =E6+E47 -> 2062494.3 | F49: =F6+F47 -> 2361158.6 | G49: =G6+G47 -> 2903404.9 | H49: =H6+H47 -> 3647205.2 | I49: =I6+I47 -> 4462084.2 | J49: =J6+J47 -> 5079457.9 | K49: =SUM(D49:J49) -> 22049313

Sheet Customer churnout
B1: Coresphere100 Technologies Pvt. Ltd.
B2: Month Wise Customer Churn Out
B4: Particulars | C4: For the month ended | D4: For the month ended | E4: For the month ended | F4: For the month ended | G4: For the month ended | H4: For the month ended | I4: For the month ended | J4: For the month ended | K4: For the month ended | L4: For the month ended
C5: 45658 | D5: 45689 | E5: 45717 | F5: 45748 | G5: 45778 | H5: 45809 | I5: 45839 | J5: 45870 | K5: 45901 | L5: 45931 | M5: Remarks
B6: No. of active subscriber at beginning of month | C6: 16 | D6: =C9 -> 27 | E6: =D9 -> 35 | F6: =E9 -> 57 | G6: =F9 -> 117 | H6: =G9 -> 143 | I6: =H9 -> 158 | J6: =I9 -> 195 | K6: =J9 -> 219 | L6: =K9 -> 245 | M6: Refer active subscriber and Deletion tab
B7: Add: New additions | C7: 15 | D7: 13 | E7: 24 | F7: 61 | G7: 37 | H7: 32 | I7: 48 | J7: 38 | K7: 39 | L7: 49
B8: Less: Deletions | C8: 4 | D8: 5 | E8: 2 | F8: 1 | G8: 11 | H8: 17 | I8: 11 | J8: 14 | K8: 13 | L8: 6
B9: No. of active subscribers at end of month | C9: =C6+C7-C8 -> 27 | D9: =D6+D7-D8 -> 35 | E9: =E6+E7-E8 -> 57 | F9: =F6+F7-F8 -> 117 | G9: =G6+G7-G8 -> 143 | H9: =H6+H7-H8 -> 158 | I9: =I6+I7-I8 -> 195 | J9: =J6+J7-J8 -> 219 | ... L9: =L6+L7-L8 -> 288

Sheet Pivot
A2: Month Wise
B3: Data
A4: Payment Cycle | B4: Sum of Invoiced amount for April | C4: Sum of Invoiced amount for MAY | D4: Sum of June in months | E4: Sum of July in months | F4: Sum of Aug Sales in months | G4: Sum of Sept Sales in months | H4: Sum of Oct Sales in months
A5: 1 month-Upfront | B5: 219140 | C5: 272830.01 | D5: 366920 | E5: 525350 | F5: 67820 | G5: 187792.47 | H5: 239824.54
A6: 2 months- Upfront | B6: 105020 | C6: 148090 | D6: 84370 | E6: 11800 | F6: 11800
A7: 3 months subscription, Monthly | B7: 177000 | C7: 177000 | D7: 177000 | F7: 0
A8: 3 months subscription, upfront | B8: 207025.67 | C8: 162276.67 | D8: 139266.67 | E8: 47226.667 | F8: 45626.667 | G8: 24386.667 | H8: 24386.667
A9: Annual subscription, Quarterly upfront | B9: 56966.667 | C9: 56966.667 | D9: 113606.67 | E9: 213316.67 | F9: 419843.33 | G9: 526773.33 | H9: 603733.33
A10: Annual Upfront | B10: 770920.33 | C10: 907320 | D10: 1187652.3 | E10: 1707479.8 | F10: 1974898.9 | G10: 2325639.7 | H10: 2416909.7
A11: Annual-Monthly | B11: 81459 | C11: 92275.667 | D11: 108175.67 | E11: 186251.67 | F11: 186251.67 | G11: 262531.67 | H11: 380851.67
A12: Three Installments of 50k | B12: 13250 | C12: 13250 | D12: 13250 | E12: 13250 | F12: 13250 | G12: 13250 | H12: 13250
A13: 2 months subscription, Monthly | B13: 47200 | C13: 35400 | D13: 10620 | E13: 10620 | F13: 50640.88 | G13: 50640.88
A14: 5 months subscription, Monthly | F14: 0
A15: 4 months subscription, Monthly | B15: 11800 | C15: 11800 | D15: 11800 | E15: 11800 | F15: 0
A16: 6 month-Upfront | B16: 243183 | C16: 266547 | D16: 398510.33 | E16: 455368.3 | F16: 551788.67 | G16: 581205.33 | H16: 575378.67
A17: Annual- Half Yearly Payment | B17: 61165.667 | C17: 347905.67 | D17: 347905.67 | E17: 373767.33 | F17: 1158310 | G17: 1209148.3 | H17: 1432679.7
A18: (empty)
A19: 10 -Days -Upfront | E19: 9440 | F19: 0
A20: 2 Year- Upfront | E20: 4745.67 | F20: 4745.67 | G20: 4745.67 | H20: 4745.67
A21: 38 -Days -Upfront | D21: 5822.3684 | F21: 0
A22: 12 -Days -Upfront | F22: 4111
A23: 11 months subscription, Monthly | D23: 0 | E23: 7080 | F23: 7080 | G23: 7080 | H23: 7080
A24: 5 month-Upfront | G24: 4130 | H24: 4130
A25: 19 -Days -Upfront | E25: 40819.174 | F25: 13018
A26: 1 year & 1 months-Monthly | B26: 11800 | C26: 11800 | D26: 11800 | E26: 11800 | F26: 11800 | G26: 11800 | H26: 11800
A27: 18 month-Half Yearly Payment | B27: 6883.3333 | C27: 6883.3333 | D27: 6883.3333 | E27: 6883.3333 | F27: 6883.3333 | G27: 6883.3333 | H27: 6883.3333
A28: 9 months subscription, Monthly | E28: 19912.5 | F28: 19912.5 | G28: 17700 | H28: 17700
A29: 15 -Days -Upfront | G29: 4720
A30: 13 month-Upfront | G30: 0 | H30: 0
A31: 8 months & 23 days - Half Yearly Payment | G31: 183844.96 | H31: 183844.96
A32: 6 months subscription, Quarterly upfront | B32: 36399 | C32: 36399 | D32: 36399 | E32: 36399
A33: 6 months subscription, Monthly | B33: 5900 | C33: 5900 | D33: 5900 | E33: 5900 | F33: 5900 | H33: 180195.44
A34: 13 month-Monthly
A35: 10 months | H35: 3894
A36: 3 months- Upfront
A37: 9 months subscription, Upfront | H37: 20075.226
A38: 2 month & 13 Days-Upfront | H38: 9006.8169
A39: 9 months & 23 days subscription, Upfront | H39: 5151.3983
A40: Total Result | B40: 2055112.7 | C40: 2552644 | D40: 3025882 | E40: 3699210.1 | F40: 4553680.6 | G40: 5422272.4 | H40: 6141521.1
A45: Date wise
...

Sheet FY 25-26-Accrual
A1: Coresphere100 Technologies Pvt. Ltd. | F1: Contracts expiring within | G1: 30 | H1: 45777 | I1: 45748 | N1: 45778 | O1: 45808 | R1: 45809 | W1: 45870
A2: Invoices Details | I2: =SUBTOTAL(9,I4:I1944) -> 64954444 | J2: =SUBTOTAL(9,J4:J1944) -> 2055112.7 | K2: =SUBTOTAL(9,K4:K1944) -> 2552644 | N2: =SUBTOTAL(9,N4:N1944) -> 1759682.3 | P2: =SUBTOTAL(9,P4:P1944) -> 2405272.2 | Q2: =SUBTOTAL(9,Q4:Q1944) -> 3025882 | R2: 45838 | S2: =SUBTOTAL(9,S4:S1944) -> 2757193.1 | T2: =SUBTOTAL(9,T4:T1944) -> 3675610.1 | U2: 45869 | V2: =SUBTOTAL(9,V4:V1944) -> 3382483.7 | W2: 45900 | X2: =SUBTOTAL(9,X4:X1944) -> 4553680.6 | Y2: =SUBTOTAL(9,Y4:Y1944) -> 4278677.1 | Z2: 45930 | AA2: =SUBTOTAL(9,AA4:AA1944) -> 5422252.7 | AB2: =SUBTOTAL(9,AB4:AB1944) -> 5248254 | AC2: 45961 | AD2: =SUBTOTAL(9,AD4:AD1944) -> 0 | AE2: =SUBTOTAL(9,AE4:AE1944) -> 0
A3: Contract | B3: Months | C3: Customer Name | D3: Invoice | E3: Nature of service | F3: Start Date | G3: End Date | H3: Payment Cycle | I3: Contract Amount | J3: Invoiced amount for April | K3: Invoiced amount for MAY | L3: Contract period | M3: Days in April | N3: April Sales (Days Wise) | O3: Days in May | P3: May Sales (Days Wise) | Q3: June in months | R3: Days in June | S3: June in days | T3: July in months | U3: Days in July | V3: July in days | W3: Days in Aug | X3: Aug Sales in months | Y3: Aug Sales in days | Z3: Days in Sept | AA3: Sept Sales in months | AB3: Sept Sales in days | AC3: Days in Oct | AD3: Oct Sales in months | AE3: Oct Sales in days
A4: 0 | B4: 45748 | C4: Touchstone Partners | D4: INV-25-26-000001 | E4: subscription based service | F4: 45748 | G4: 45838 | H4: 3 months subscription, upfront | I4: =60000+10800 -> 70800 | J4: 23600 | K4: =I4/3 -> 23600 | L4: =G4-F4+1 -> 91 | M4: =$H$1-F4+1 -> 30 | N4: =I4/L4*M4 -> 23340.659 | O4: =IF(F4<$O$1,31,$O$1-F4) -> 31 | P4: =O4*I4/L4 -> 24118.681 | Q4: =I4/3 -> 23600 | R4: =IF(F4<$R$2,30,$R$2-F4) -> 30 | S4: =R4*I4/L4 -> 23340.659 | U4: =IF(F5<$U$2,31,$U$2-F5) -> 31 | W4: 0 | X4: 0 | Y4: 0
A5: Closed- May 25 | B5: 45748 | C5: Bimal Rajasekhar | D5: INV-25-26-000002 | E5: subscription based service | F5: 45748 | G5: 45808 | H5: 2 months- Upfront | I5: 35400 | J5: 17700 | K5: =I5/2 -> 17700 | L5: =G5-F5+1 -> 61 | M5: =$H$1-F5+1 -> 30 | N5: =I5/L5*M5 -> 17409.836 | O5: =IF(F5<$O$1,31,$O$1-F5) -> 31 | P5: =O5*I5/L5 -> 17990.164 | R5: =IF(F5<$R$2,30,$R$2-F5) -> 30 | U5: =IF(F6<$U$2,31,$U$2-F6) -> 31 | W5: 0 | X5: 0 | Y5: 0
A6: 0 | B6: 45748 | C6: Veritas Legal Advocates and Solicitors | D6: INV-25-26-000003 | E6: subscription based service | F6: 45749 | G6: 45932 | H6: 6 month-Upfront | I6: =993600+178848 -> 1172448 | J6: 195408 | K6: =I6/6 -> 195408 | L6: =G6-F6+1 -> 184 | M6: =$H$1-F6+1 -> 29 | N6: =I6/L6*M6 -> 184788 | O6: =IF(F6<$O$1,31,$O$1-F6) -> 31 | P6: =O6*I6/L6 -> 197532 | Q6: =I6/6 -> 195408 | R6: =IF(F6<$R$2,30,$R$2-F6) -> 30 | S6: =R6*I6/L6 -> 191160 | T6: =I6/6 -> 195408 | U6: =IF(F7<$U$2,31,$U$2-F7) -> 31 | V6: =I6*U6/L6 -> 197532 | W6: =IF(F6<$W$2,31,$W$2-F6) -> 31 | X6: =I6/6 -> 195408 | Y6: =I6*W6/L6 -> 197532 | Z6: =IF(F6<$Z$2,30,$Z$2-I6) -> 30 | AA6: =I6/6 -> 195408 | AB6: =Z6*I6/L6 -> 191160
A7: 0 | B7: Apr & May 25 | C7: LEGALOGIC CONSULTING LLP | D7: INV-25-26-000004,104 | E7: subscription based service | F7: 45748 | G7: 45808 | H7: 2 months subscription, Monthly | I7: =35400*2 -> 70800 | J7: 35400 | K7: 35400 | L7: =G7-F7+1 -> 61 | M7: =$H$1-F7+1 -> 30 | N7: =I7/L7*M7 -> 34819.672 | O7: =IF(F7<$O$1,31,$O$1-F7) -> 31 | P7: =O7*I7/L7 -> 35980.328 | R7: =IF(F7<$R$2,30,$R$2-F7) -> 30 | U7: =IF(F8<$U$2,31,$U$2-F8) -> 31 | W7: 0 | X7: 0 | Y7: 0
A8: 0 | B8: 45748 | C8: VACUITAS COUNSELLOR LLP | D8: INV-25-26-000005 | E8: subscription based service | F8: 45750 | G8: 46114 | H8: Annual Upfront | I8: 116820 | J8: 9735 | K8: =I8/12 -> 9735 | L8: =G8-F8+1 -> 365 | M8: =$H$1-F8+1 -> 28 | N8: =I8/L8*M8 -> 8961.5342 | O8: =IF(F8<$O$1,31,$O$1-F8) -> 31 | P8: =O8*I8/L8 -> 9921.6986 | Q8: =I8/12 -> 9735 | R8: =IF(F8<$R$2,30,$R$2-F8) -> 30 | S8: =R8*I8/L8 -> 9601.6438 | T8: =I8/12 -> 9735 | U8: =IF(F9<$U$2,31,$U$2-F9) -> 31 | V8: =I8*U8/L8 -> 9921.6986 | W8: =IF(F8<$W$2,31,$W$2-F8) -> 31 | X8: =I8/12 -> 9735 | Y8: =I8*W8/L8 -> 9921.6986 | Z8: =IF(F8<$Z$2,30,$Z$2-I8) -> 30 | AA8: =I8/12 -> 9735 | AB8: =I8*Z8/L8 -> 9601.6438
A9: Closed-Apr 25 | B9: 45748 | C9: Tvashta Law | D9: INV-25-26-000006 | E9: One time work | F9: 45748 | G9: 45777 | H9: 1 month-Upfront | I9: 2360 | J9: 2360 | L9: =G9-F9+1 -> 30 | M9: 30 | N9: =I9/L9*M9 -> 2360 | O9: 0 | P9: =O9*I9/L9 -> 0 | R9: =IF(F9<$R$2,30,$R$2-F9) -> 30 | U9: =IF(F10<$U$2,31,$U$2-F10) -> 31 | W9: 0 | X9: 0 | Y9: 0
A10: 0 | B10: 45748 | C10: U. S. GANDHI & CO. | D10: INV-25-26-000007 | E10: subscription based service | F10: 45754 | G10: 45814 | H10: 2 months- Upfront | I10: 9440 | J10: =I10/2 -> 4720 | K10: =I10/2 -> 4720 | L10: =G10-F10+1 -> 61 | M10: =$H$1-F10+1 -> 24 | N10: =I10/L10*M10 -> 3714.0984 | O10: =IF(F10<$O$1,31,$O$1-F10) -> 31 | P10: =O10*I10/L10 -> 4797.377 | R10: =G10-$R$1+1 -> 6 | S10: =R10*I10/L10 -> 928.52459 | U10: =IF(F11<$U$2,31,$U$2-F11) -> 31 | W10: 0 | X10: 0 | Y10: 0
A11: Credit Note Issue | B11: 45748 | C11: Advocate Rohit Jaiswal | D11: INV-25-26-000009,00107,00177 | E11: subscription based service | F11: 45762 | G11: 45791 | H11: 1 month-Upfront | I11: =5900*1 -> 5900 | J11: 5900 | K11: 0 | L11: =G11-F11+1 -> 30 | M11: =$H$1-F11+1 -> 16 | N11: =I11/L11*M11 -> 3146.6667 | O11: =G11-N1+1 -> 14 | P11: =O11*I11/L11 -> 2753.3333 | S11: =R11*I11/L11 -> 0 | V11: =I11*U11/L11 -> 0 | W11: 0 | X11: 0 | Y11: 0
A12: 0 | B12: 45748 | C12: Dileep Poolakkot | D12: INV-25-26-000010 | E12: subscription based service | F12: 45755 | G12: 46119 | H12: Annual Upfront | I12: =60000*118% -> 70800 | J12: 5900 | K12: =I12/12 -> 5900 | L12: =G12-F12+1 -> 365 | M12: =$H$1-F12+1 -> 23 | N12: =I12/L12*M12 -> 4461.3699 | O12: =IF(F12<$O$1,31,$O$1-F12) -> 31 | P12: =O12*I12/L12 -> 6013.1507 | Q12: =I12/12 -> 5900 | R12: =IF(F12<$R$2,30,$R$2-F12) -> 30 | S12: =R12*I12/L12 -> 5819.1781 | T12: =I12/12 -> 5900 | U12: =IF(F13<$U$2,31,$U$2-F13) -> 31 | V12: =I12*U12/L12 -> 6013.1507 | W12: =IF(F12<$W$2,31,$W$2-F12) -> 31 | X12: =I12/12 -> 5900 | Y12: =I12*W12/L12 -> 6013.1507 | Z12: =IF(F12<$Z$2,30,$Z$2-I12) -> 30 | AA12: =I12/12 -> 5900 | AB12: =I12*Z12/L12 -> 5819.1781
A13: 0 | B13: 45748 | C13: Utkarsh Joshi | D13: INV-25-26-000011 | E13: subscription based service | F13: 45755 | G13: 45815 | H13: 2 months- Upfront | I13: 7080 | J13: 3540 | K13: =I13/2 -> 3540 | L13: =G13-F13+1 -> 61 | M13: =$H$1-F13+1 -> 23 | N13: =I13/L13*M13 -> 2669.5082 | O13: =IF(F13<$O$1,31,$O$1-F13) -> 31 | P13: =O13*I13/L13 -> 3598.0328 | R13: 7 | S13: =R13*I13/L13 -> 812.45902 | U13: =IF(F14<$U$2,31,$U$2-F14) -> 31 | W13: 0 | X13: 0 | Y13: 0
A14: 0 | B14: 45748 | C14: Karan Butalia | D14: INV-25-26-000012 | E14: subscription based service | F14: 45755 | G14: 45815 | H14: 2 months- Upfront | I14: 4720 | J14: 2360 | K14: 2360 | L14: =G14-F14+1 -> 61 | M14: =$H$1-F14+1 -> 23 | N14: =I14/L14*M14 -> 1779.6721 | O14: =IF(F14<$O$1,31,$O$1-F14) -> 31 | P14: =O14*I14/L14 -> 2398.6885 | R14: 7 | S14: =R14*I14/L14 -> 541.63934 | U14: =IF(F15<$U$2,31,$U$2-F15) -> 31 | W14: 0 | X14: 0 | Y14: 0
A15: 0 | B15: Jan & Apr & July & Oct 25 | C15: Agama Law Associates | D15: INV- 46, INV-25-26-000013, 277, 483 | E15: subscription based service | F15: 45658 | G15: 46022 | H15: Annual subscription, Quarterly upfront | I15: =80000*4 -> 320000 | J15: 26666.667 | K15: =I15/12 -> 26666.667 | L15: =G15-F15+1 -> 365 | M15: =IF(F17<$H$1,30,$H$1-F17) -> 30 | N15: =I15/L15*M15 -> 26301.37 | O15: =IF(F15<$O$1,31,$O$1-F15) -> 31 | P15: =O15*I15/L15 -> 27178.082 | Q15: =I15/12 -> 26666.667 | R15: =IF(F15<$R$2,30,$R$2-F15) -> 30 | S15: =R15*I15/L15 -> 26301.37 | T15: =I15/12 -> 26666.667 | U15: =IF(F16<$U$2,31,$U$2-F16) -> 31 | V15: =I15*U15/L15 -> 27178.082 | W15: =IF(F15<$W$2,31,$W$2-F15) -> 31 | X15: =I15/12 -> 26666.667 | Y15: =I15*W15/L15 -> 27178.082 | Z15: =IF(F15<$Z$2,30,$Z$2-I15) -> 30 | AA15: =I15/12 -> 26666.667 | AB15: =I15*Z15/L15 -> 26301.37
A16: Closed- May 25 | B16: 45748 | C16: RAJANI ASSOCIATES | D16: INV-25-26-000014 | E16: subscription based service | F16: 45757 | G16: 45786 | H16: 1 month-Upfront | I16: 24780 | J16: 24780 | L16: =G16-F16+1 -> 30 | M16: =$H$1-F16+1 -> 21 | N16: =I16/L16*M16 -> 17346 | O16: =L16-M16 -> 9 | P16: =O16*I16/L16 -> 7434 | R16: =IF(F16<$R$2,30,$R$2-F16) -> 30 | U16: =IF(F17<$U$2,31,$U$2-F17) -> 31 | W16: 0 | X16: 0 | Y16: 0
A17: 0 | B17: 45748 | C17: Venkatesh Dhond | D17: INV-25-26-000015 | E17: subscription based service | F17: 45716 | G17: 45896 | H17: 6 month-Upfront | I17: 100890 | J17: 16815 | K17: =I17/6 -> 16815 | L17: =G17-F17+1 -> 181 | M17: =IF(F17<H1,30,H1-F17) -> 30 | N17: =I17/L17*M17 -> 16722.099 | O17: =IF(F17<$O$1,31,$O$1-F17) -> 31 | P17: =O17*I17/L17 -> 17279.503 | Q17: =I17/6 -> 16815 | R17: =IF(F17<$R$2,30,$R$2-F17) -> 30 | S17: =R17*I17/L17 -> 16722.099 | T17: =I17/6 -> 16815 | U17: =IF(F18<$U$2,31,$U$2-F18) -> 31 | V17: =I17*U17/L17 -> 17279.503 | W17: =G17-$W$1+1 -> 27 | X17: 0 | Y17: =I17*W17/L17 -> 15049.89
A18: 0 | B18: Mar to June 25 | C18: Harshit Malik | D18: INV-000111, INV-25-26-000016, 0109 | E18: subscription based service | F18: 45725 | G18: 45786 | H18: 2 months subscription, Monthly | I18: =11800*4-11800*2 -> 23600 | J18: 11800 | L18: =G18-F18+1 -> 62 | M18: =IF(F18<H3,30,H3-F18) -> 30 | N18: =I18/L18*M18 -> 11419.355 | O18: 9 | P18: =O18*I18/L18 -> 3425.8065 | R18: =30 -> 30 | U18: =IF(F19<$U$2,31,$U$2-F19) -> 31 | W18: 0 | X18: 0 | Y18: 0
A19: 0 | B19: 45748 | C19: PSN Legal Advocates and Legal Consultants | D19: INV-25-26-000017 | E19: subscription based service | F19: 45757 | G19: 46121 | H19: Annual Upfront | I19: 177015 | J19: 14751.25 | K19: =I19/12 -> 14751.25 | L19: =G19-F19+1 -> 365 | M19: =$H$1-F19+1 -> 21 | N19: =I19/L19*M19 -> 10184.425 | O19: =IF(F19<$O$1,31,$O$1-F19) -> 31 | P19: =O19*I19/L19 -> 15034.151 | Q19: =I19/12 -> 14751.25 | R19: =IF(F19<$R$2,30,$R$2-F19) -> 30 | S19: =R19*I19/L19 -> 14549.178 | T19: =I19/12 -> 14751.25 | U19: =IF(F20<$U$2,31,$U$2-F20) -> 31 | V19: =I19*U19/L19 -> 15034.151 | W19: =IF(F19<$W$2,31,$W$2-F19) -> 31 | X19: =I19/12 -> 14751.25 | Y19: =I19*W19/L19 -> 15034.151 | Z19: =IF(F19<$Z$2,30,$Z$2-I19) -> 30 | AA19: =I19/12 -> 14751.25 | AB19: =I19*Z19/L19 -> 14549.178
A20: 0 | B20: Apr to July 25 | C20: Swapna Sheshadri | D20: INV-25-26-000019, 113, 0184, 259 | E20: subscription based service | F20: 45757 | G20: 45878 | H20: 4 months subscription, Monthly | I20: =11800*4 -> 47200 | J20: 11800 | K20: 11800 | L20: =G20-F20+1 -> 122 | M20: =$H$1-F20+1 -> 21 | N20: =I20/L20*M20 -> 8124.5902 | O20: =IF(F20<$O$1,31,$O$1-F20) -> 31 | P20: =O20*I20/L20 -> 11993.443 | Q20: =I20/4 -> 11800 | R20: =IF(F20<$R$2,30,$R$2-F20) -> 30 | S20: =R20*I20/L20 -> 11606.557 | T20: =I20/4 -> 11800 | U20: =IF(F21<$U$2,31,$U$2-F21) -> 31 | V20: =I20*U20/L20 -> 11993.443 | W20: =G20-$W$1+1 -> 9 | Y20: =W20*I20/L20 -> 3481.9672
A21: 0 | B21: 45748 | C21: Vutts & Associates LLP | D21: INV-25-26-000020 | E21: subscription based service | F21: 45758 | G21: 45848 | H21: 3 months subscription, upfront | I21: 35400 | J21: 11800 | K21: =I21/3 -> 11800 | L21: =G21-F21+1 -> 91 | M21: =$H$1-F21+1 -> 20 | N21: =I21/L21*M21 -> 7780.2198 | O21: =IF(F21<$O$1,31,$O$1-F21) -> 31 | P21: =O21*I21/L21 -> 12059.341 | Q21: =I21/3 -> 11800 | R21: =IF(F21<$R$2,30,$R$2-F21) -> 30 | S21: =R21*I21/L21 -> 11670.33 | U21: =G21-$R$2 -> 10 | V21: =U21*I21/L21 -> 3890.1099 | W21: 0 | X21: 0 | Y21: 0
A22: 0 | B22: Feb Apr to Oct 25 | C22: Darius J. Khambata | D22: INV-000085, INV-25-26-000021,INV-25-26-000022, 148,178, 248, 337, 416, 500 | E22: subscription based service | F22: 45695 | G22: 46059 | H22: Annual-Monthly | I22: =20000*12 -> 240000 | J22: 20000 | K22: =I22/12 -> 20000 | L22: =G22-F22+1 -> 365 | M22: =IF(F22<H7,30,H7-F22) -> 30 | N22: =I22/L22*M22 -> 19726.027 | O22: =IF(F22<$O$1,31,$O$1-F22) -> 31 | P22: =O22*I22/L22 -> 20383.562 | Q22: =I22/12 -> 20000 | R22: =IF(F22<$R$2,30,$R$2-F22) -> 30 | S22: =R22*I22/L22 -> 19726.027 | T22: =I22/12 -> 20000 | U22: =IF(F23<$U$2,31,$U$2-F23) -> 31 | V22: =I22*U22/L22 -> 20383.562 | W22: =IF(F22<$W$2,31,$W$2-F22) -> 31 | X22: =I22/12 -> 20000 | Y22: =I22*W22/L22 -> 20383.562 | Z22: =IF(F22<$Z$2,30,$Z$2-I22) -> 30 | AA22: =I22/12 -> 20000 | AB22: =I22*Z22/L22 -> 19726.027
A23: 0 | B23: 45748 | C23: Miglani Varma & Co. | D23: INV-25-26-000023 | E23: subscription based service | F23: 45758 | G23: 45848 | H23: 3 months subscription, upfront | I23: 17700 | J23: 5900 | K23: =I23/3 -> 5900 | L23: =G23-F23+1 -> 91 | M23: =$H$1-F23+1 -> 20 | N23: =I23/L23*M23 -> 3890.1099 | O23: =IF(F23<$O$1,31,$O$1-F23) -> 31 | P23: =O23*I23/L23 -> 6029.6703 | Q23: =I23/3 -> 5900 | R23: =IF(F23<$R$2,30,$R$2-F23) -> 30 | S23: =R23*I23/L23 -> 5835.1648 | U23: =G23-$R$2 -> 10 | V23: =U23*I23/L23 -> 1945.0549 | W23: 0 | X23: 0 | Y23: 0
A24: Closed- May 25 | B24: 45748 | C24: Venkatesh Mohanraj | D24: INV-25-26-000024 | E24: subscription based service | F24: 45759 | G24: 45788 | H24: 1 month-Upfront | I24: 5900 | J24: 5900 | L24: =G24-F24+1 -> 30 | M24: =$H$1-F24+1 -> 19 | N24: =I24/L24*M24 -> 3736.6667 | O24: =L24-M24 -> 11 | P24: =O24*I24/L24 -> 2163.3333 | R24: =IF(F24<$R$2,30,$R$2-F24) -> 30 | U24: =IF(F25<$U$2,31,$U$2-F25) -> 31 | W24: 0 | X24: 0 | Y24: 0
A25: Closed- May 25 | B25: 45748 | C25: Jade Lex Partners | D25: INV-25-26-000025 | E25: subscription based service | F25: 45759 | G25: 45788 | H25: 1 month-Upfront | I25: 7080 | J25: 7080 | L25: =G25-F25+1 -> 30 | M25: =$H$1-F25+1 -> 19 | N25: =I25/L25*M25 -> 4484 | O25: =L25-M25 -> 11 | P25: =O25*I25/L25 -> 2596 | R25: =IF(F25<$R$2,30,$R$2-F25) -> 30 | U25: =IF(F26<$U$2,31,$U$2-F26) -> 31 | W25: 0 | X25: 0 | Y25: 0
A26: Closed- May 25 | B26: 45748 | C26: Alankrit Bajpai | D26: INV-25-26-000026 | E26: subscription based service | F26: 45759 | G26: 45788 | H26: 1 month-Upfront | I26: 5900 | J26: 5900 | L26: =G26-F26+1 -> 30 | M26: =$H$1-F26+1 -> 19 | N26: =I26/L26*M26 -> 3736.6667 | O26: =L26-M26 -> 11 | P26: =O26*I26/L26 -> 2163.3333 | R26: =IF(F26<$R$2,30,$R$2-F26) -> 30 | U26: =IF(F27<$U$2,31,$U$2-F27) -> 31 | W26: 0 | X26: 0 | Y26: 0
A27: Closed- May 25 | B27: 45748 | C27: Badar Durrez | D27: INV-25-26-000028 | E27: subscription based service | F27: 45760 | G27: 45789 | H27: 1 month-Upfront | I27: 5900 | J27: 5900 | L27: =G27-F27+1 -> 30 | M27: =$H$1-F27+1 -> 18 | N27: =I27/L27*M27 -> 3540 | O27: =L27-M27 -> 12 | P27: =O27*I27/L27 -> 2360 | R27: =IF(F27<$R$2,30,$R$2-F27) -> 30 | U27: =IF(F28<$U$2,31,$U$2-F28) -> 31 | W27: 0 | X27: 0 | Y27: 0
A28: 0 | B28: 45748 | C28: Rashmikant and Partners | D28: INV-25-26-000029 | E28: subscription based service | F28: 45761 | G28: 46125 | H28: Annual Upfront | I28: 259600 | J28: 21633.333 | K28: =I28/12 -> 21633.333 | L28: =G28-F28+1 -> 365 | M28: =$H$1-F28+1 -> 17 | N28: =I28/L28*M28 -> 12090.959 | O28: =IF(F28<$O$1,31,$O$1-F28) -> 31 | P28: =O28*I28/L28 -> 22048.219 | Q28: =I28/12 -> 21633.333 | R28: =IF(F28<$R$2,30,$R$2-F28) -> 30 | S28: =R28*I28/L28 -> 21336.986 | T28: =I28/12 -> 21633.333 | U28: =IF(F29<$U$2,31,$U$2-F29) -> 31 | V28: =I28*U28/L28 -> 22048.219 | W28: =IF(F28<$W$2,31,$W$2-F28) -> 31 | X28: =I28/12 -> 21633.333 | Y28: =I28*W28/L28 -> 22048.219 | Z28: =IF(F28<$Z$2,30,$Z$2-I28) -> 30 | AA28: =I28/12 -> 21633.333 | AB28: =I28*Z28/L28 -> 21336.986
A29: 0 | B29: Apr to June 25 | C29: TLH, Advocates & Solicitors | D29: INV-25-26-000030, 124, 198,271 | E29: subscription based service | F29: 45762 | G29: 45852 | H29: 3 months subscription, Monthly | I29: =177000*3 -> 531000 | J29: 177000 | K29: =I29/3 -> 177000 | L29: =G29-F29+1 -> 91 | M29: 16 | N29: =I29/L29*M29 -> 93362.637 | O29: =IF(F29<$O$1,31,$O$1-F29) -> 31 | P29: =O29*I29/L29 -> 180890.11 | Q29: =I29/3 -> 177000 | R29: =IF(F29<$R$2,30,$R$2-F29) -> 30 | S29: =R29*I29/L29 -> 175054.95 | U29: 14 | V29: =I29*U29/L29 -> 81692.308 | W29: 0 | X29: 0 | Y29: 0
A30: 0 | B30: 45748 | C30: Shreeyash Lalit | D30: INV-25-26-000032 | E30: subscription based service | F30: 45762 | G30: 45944 | H30: 6 month-Upfront | I30: 42480 | J30: 7080 | K30: =I30/6 -> 7080 | L30: =G30-F30+1 -> 183 | M30: =$H$1-F30+1 -> 16 | N30: =I30/L30*M30 -> 3714.0984 | O30: =IF(F30<$O$1,31,$O$1-F30) -> 31 | P30: =O30*I30/L30 -> 7196.0656 | Q30: =I30/6 -> 7080 | R30: =IF(F30<$R$2,30,$R$2-F30) -> 30 | S30: =R30*I30/L30 -> 6963.9344 | T30: =I30/6 -> 7080 | U30: =IF(F31<$U$2,31,$U$2-F31) -> 31 | V30: =I30*U30/L30 -> 7196.0656 | W30: =IF(F30<$W$2,31,$W$2-F30) -> 31 | X30: =I30/6 -> 7080 | Y30: =I30*W30/L30 -> 7196.0656 | Z30: =IF(F30<$Z$2,30,$Z$2-I30) -> 30 | AA30: =I30/6 -> 7080 | AB30: =Z30*I30/L30 -> 6963.9344
A31: 0 | B31: 45748 | C31: Dewani Associates | D31: INV-25-26-000033 | E31: subscription based service | F31: 45762 | G31: 45823 | H31: 2 months- Upfront | I31: 23600 | J31: 11800 | K31: =I31/2 -> 11800 | L31: =G31-F31+1 -> 62 | M31: =$H$1-F31+1 -> 16 | N31: =I31/L31*M31 -> 6090.3226 | O31: =IF(F31<$O$1,31,$O$1-F31) -> 31 | P31: =O31*I31/L31 -> 11800 | R31: 15 | S31: =R31*I31/L31 -> 5709.6774 | U31: =IF(F32<$U$2,31,$U$2-F32) -> 31 | W31: 0 | X31: 0 | Y31: 0
A32: 0 | B32: Apr to Oct 25 | C32: R. Vishnu Kumar, Advocate | D32: INV-25-26-000034, 125, 199, 272, 358, 528 | E32: subscription based service | F32: 45762 | G32: 46126 | H32: Annual-Monthly | I32: =20000*12 -> 240000 | J32: 20000 | K32: 20000 | L32: =G32-F32+1 -> 365 | M32: =$H$1-F32+1 -> 16 | N32: =I32/L32*M32 -> 10520.548 | O32: =IF(F32<$O$1,31,$O$1-F32) -> 31 | P32: =O32*I32/L32 -> 20383.562 | Q32: =I32/12 -> 20000 | R32: =IF(F32<$R$2,30,$R$2-F32) -> 30 | S32: =R32*I32/L32 -> 19726.027 | T32: =I32/12 -> 20000 | U32: =IF(F33<$U$2,31,$U$2-F33) -> 31 | V32: =I32*U32/L32 -> 20383.562 | W32: =IF(F32<$W$2,31,$W$2-F32) -> 31 | X32: =I32/12 -> 20000 | Y32: =I32*W32/L32 -> 20383.562 | Z32: =IF(F32<$Z$2,30,$Z$2-I32) -> 30 | AA32: =I32/12 -> 20000 | AB32: =I32*Z32/L32 -> 19726.027
A33: 0 | B33: Mar & Apr 25 | C33: Yash Momaya | D33: INV-25-26-000035, 0127, 0200 | E33: subscription based service | F33: 45763 | G33: 45792 | H33: 1 month-Upfront | I33: =11800*3-11800*2 -> 11800 | J33: 11800 | L33: =G33-F33+1 -> 30 | M33: =$H$1-F33+1 -> 15 | N33: =I33/L33*M33 -> 5900 | O33: =G33-N1+1 -> 15 | P33: =O33*I33/L33 -> 5900 | Q33: 0 | R33: =IF(F33<$R$2,30,$R$2-F33) -> 30 | S33: 0 | T33: 0 | U33: =IF(F34<$U$2,31,$U$2-F34) -> 31 | V33: 0 | W33: 0 | X33: 0 | Y33: 0
A34: Closed- May 25 | B34: 45748 | C34: Chetan Dedhia | D34: INV-25-26-000036 | E34: subscription based service | F34: 45763 | G34: 45792 | H34: 1 month-Upfront | I34: 17700 | J34: 17700 | L34: =G34-F34+1 -> 30 | M34: =$H$1-F34+1 -> 15 | N34: =I34/L34*M34 -> 8850 | O34: =L34-M34 -> 15 | P34: =O34*I34/L34 -> 8850 | R34: =IF(F34<$R$2,30,$R$2-F34) -> 30 | U34: =IF(F35<$U$2,31,$U$2-F35) -> 31 | W34: 0 | X34: 0 | Y34: 0
A35: 0 | B35: 45748 | C35: NC Legal | D35: INV-25-26-000037 | E35: subscription based service | F35: 45778 | G35: 46142 | H35: Annual Upfront | I35: 80240 | K35: =I35/12 -> 6686.6667 | L35: =G35-F35+1 -> 365 | M35: =$H$1-F35+1 -> 0 | N35: =I35/L35*M35 -> 0 | O35: =$O$1-F35+1 -> 31 | P35: =O35*I35/L35 -> 6814.9041 | Q35: =I35/12 -> 6686.6667 | R35: =IF(F35<$R$2,30,$R$2-F35) -> 30 | S35: =R35*I35/L35 -> 6595.0685 | T35: =I35/12 -> 6686.6667 | U35: =IF(F36<$U$2,31,$U$2-F36) -> 31 | V35: =I35*U35/L35 -> 6814.9041 | W35: =IF(F35<$W$2,31,$W$2-F35) -> 31 | X35: =I35/12 -> 6686.6667 | Y35: =I35*W35/L35 -> 6814.9041 | Z35: =IF(F35<$Z$2,30,$Z$2-I35) -> 30 | AA35: =I35/12 -> 6686.6667 | AB35: =I35*Z35/L35 -> 6595.0685
A36: Closed- May 25 | B36: 45748 | C36: Aakash Sharma | D36: INV-25-26-000038 | E36: subscription based service | F36: 45765 | G36: 45795 | H36: 1 month-Upfront | I36: 5900 | J36: 5900 | L36: =G36-F36+1 -> 31 | M36: =$H$1-F36+1 -> 13 | N36: =I36/L36*M36 -> 2474.1935 | O36: =L36-M36 -> 18 | P36: =O36*I36/L36 -> 3425.8065 | R36: =IF(F36<$R$2,30,$R$2-F36) -> 30 | U36: =IF(F37<$U$2,31,$U$2-F37) -> 31 | W36: 0 | X36: 0 | Y36: 0
A37: Closed- May 25 | B37: 45748 | C37: Saga Legal | D37: INV-25-26-000039 | E37: subscription based service | F37: 45761 | G37: 45791 | H37: 1 month-Upfront | I37: 23600 | J37: 23600 | L37: =G37-F37+1 -> 31 | M37: =$H$1-F37+1 -> 17 | N37: =I37/L37*M37 -> 12941.935 | O37: =L37-M37 -> 14 | P37: =O37*I37/L37 -> 10658.065 | R37: =IF(F37<$R$2,30,$R$2-F37) -> 30 | U37: =IF(F38<$U$2,31,$U$2-F38) -> 31 | W37: 0 | X37: 0 | Y37: 0
A38: 0 | B38: 45748 | C38: RPV LEGAL | D38: INV-25-26-000040 | E38: subscription based service | F38: 45769 | G38: 46133 | H38: Annual Upfront | I38: 175000 | J38: 14583.333 | K38: =I38/12 -> 14583.333 | L38: =G38-F38+1 -> 365 | M38: =$H$1-F38+1 -> 9 | N38: =I38/L38*M38 -> 4315.0685 | O38: =IF(F38<$O$1,31,$O$1-F38) -> 31 | P38: =O38*I38/L38 -> 14863.014 | Q38: =I38/12 -> 14583.333 | R38: =IF(F38<$R$2,30,$R$2-F38) -> 30 | S38: =R38*I38/L38 -> 14383.562 | T38: =I38/12 -> 14583.333 | U38: =IF(F39<$U$2,31,$U$2-F39) -> 31 | V38: =I38*U38/L38 -> 14863.014 | W38: =IF(F38<$W$2,31,$W$2-F38) -> 31 | X38: =I38/12 -> 14583.333 | Y38: =I38*W38/L38 -> 14863.014 | Z38: =IF(F38<$Z$2,30,$Z$2-I38) -> 30 | AA38: =I38/12 -> 14583.333 | AB38: =I38*Z38/L38 -> 14383.562
A39: 0 | B39: 45748 | C39: AP & Partners, Advocates | D39: INV-25-26-000041 | E39: subscription based service | F39: 45771 | G39: 45860 | H39: 3 months subscription, upfront | I39: 28320 | J39: 9440 | K39: =I39/3 -> 9440 | L39: =G39-F39+1 -> 90 | M39: =$H$1-F39+1 -> 7 | N39: =I39/L39*M39 -> 2202.6667 | O39: =IF(F39<$O$1,31,$O$1-F39) -> 31 | P39: =O39*I39/L39 -> 9754.6667 | Q39: =I39/3 -> 9440 | R39: =IF(F39<$R$2,30,$R$2-F39) -> 30 | S39: =R39*I39/L39 -> 9440 | U39: =G39-$R$2 -> 22 | V39: =U39*I39/L39 -> 6922.6667 | W39: 0 | X39: 0 | Y39: 0
A40: Credit Note Issue | B40: Apr to June 25 | C40: Pranay Chitale | D40: INV-25-26-000042, 137, 213 | E40: subscription based service | F40: 45770 | G40: 45799 | H40: 1 month-Upfront | I40: =17700 -> 17700 | J40: 17700 | L40: =G40-F40+1 -> 30 | M40: =$H$1-F40+1 -> 8 | N40: =I40/L40*M40 -> 4720 | O40: =G40-N1+1 -> 22 | P40: =O40*I40/L40 -> 12980 | W40: 0 | X40: 0 | Y40: 0
...

Sheet Invoices
F2: =SUBTOTAL(9,F23:F54) -> 1496307 | H2: =SUBTOTAL(9,H23:H54) -> 1564555
A3: Months | B3: Invoice Date | C3: Invoice Number | D3: Invoice Status | E3: Customer Name | F3: Taxable Value | G3: Total Tax | H3: Total | I3: Nature
A4: 45627 | B4: 45628 | C4: INV-000027 | D4: Closed | E4: B2C | F4: 1295 | G4: 0 | H4: 1295 | I4: B2C | K4: Sum of Taxable Value | L4: Nature
A5: 45627 | B5: 45628 | C5: INV-000028 | D5: Closed | E5: Office of ASG (N. Venkatraman) | F5: 195000 | G5: 0 | H5: 195000 | I5: B2B | K5: Months | L5: B2B | M5: B2C | N5: (empty) | O5: Total Result
A6: 45627 | B6: 45635 | C6: INV-000029 | D6: Closed | E6: B2C | F6: 9164 | G6: 0 | H6: 9164 | I6: B2C | K6: 45536 | L6: 3999 | M6: 23809 | O6: 27808
A7: 45627 | B7: 45635 | C7: INV-000030 | D7: Closed | E7: Kanungo & Co. | F7: 3999 | G7: 0 | H7: 3999 | I7: B2B | K7: 45566 | L7: 49997 | M7: 41135 | O7: 91132
A8: 45627 | B8: 45638 | C8: INV-000031 | D8: Closed | E8: B2C | F8: 3786 | G8: 0 | H8: 3786 | I8: B2C | K8: 45597 | L8: 158496 | M8: 20926 | O8: 179422
A9: 45627 | B9: 45638 | C9: INV-000032 | D9: Closed | E9: Diwan Law Associates | F9: 5000 | G9: 0 | H9: 5000 | I9: B2B | K9: 45627 | L9: 514892 | M9: 34284 | O9: 549176
A10: 45627 | B10: 45639 | C10: INV-000033 | D10: Closed | E10: Aditya Sikka / Tvashta Law | F10: 45000 | G10: 0 | H10: 45000 | I10: B2B | K10: 45658 | L10: 1464041 | M10: 32266 | O10: 1496307
A11: 45627 | B11: 45639 | C11: INV-000034 | D11: Closed | E11: B2C | F11: 1493 | G11: 0 | H11: 1493 | I11: B2C | K11: 45689 | L11: 1192593 | M11: 33183 | O11: 1225776
A12: 45627 | B12: 45640 | C12: INV-000035 | D12: Closed | E12: Amrita Panda / Chambers of Amrita Panda | F12: 10000 | G12: 0 | H12: 10000 | I12: B2B | K12: 45717 | L12: 4569923 | M12: 50543 | O12: 4620466
A13: 45627 | B13: 45644 | C13: INV-000036 | D13: Closed | E13: B2C | F13: 5481 | G13: 0 | H13: 5481 | I13: B2C | K13: 45748 | L13: 4040388 | M13: 42252 | O13: 4082640
A14: 45627 | B14: 45644 | C14: INV-000037 | D14: Closed | E14: Ish Jain / Regius Partners LLP | F14: 146994 | G14: 0 | H14: 146994 | I14: B2B | K14: 45778 | L14: 4666763 | M14: 24128 | O14: 4690891
A15: 45627 | B15: 45645 | C15: INV-000038 | D15: Closed | E15: The Guild | Advocates & Associate Counsel | F15: 60000 | G15: 0 | H15: 60000 | I15: B2B | K15: 45809 | L15: 3054847.7 | M15: 24554.28 | O15: 3079401.9
A16: 45627 | B16: 45648 | C16: INV-000039 | D16: Closed | E16: B2C | F16: 2293 | G16: 0 | H16: 2293 | I16: B2C | K16: 45839 | L16: 8195261 | M16: 19474 | O16: 8214735
A17: 45627 | B17: 45648 | C17: INV-000040 | D17: Closed | E17: Manish kelker | F17: 3999 | G17: 0 | H17: 3999 | I17: B2B | K17: 45870 | L17: 9351621 | M17: 18627 | O17: 9370248
A18: 45627 | B18: 45651 | C18: INV-000041 | D18: Closed | E18: B2C | F18: 2095 | G18: 0 | H18: 2095 | I18: B2C | K18: 45901 | L18: 4189179.5 | M18: 14394.92 | O18: 4203574.5
A19: 45627 | B19: 45651 | C19: INV-000042 | D19: Closed | E19: Abhimanyu Garg / Methodica Legal | F19: 36900 | G19: 0 | H19: 36900 | I19: B2B | K19: (empty)
A20: 45627 | B20: 45655 | C20: INV-000043 | D20: Closed | E20: B2C | F20: 3687 | G20: 0 | H20: 3687 | I20: B2C | K20: 45931 | L20: 5730227.7 | M20: 13549.16 | O20: 5743776.8
A21: 45627 | B21: 45655 | C21: INV-000044 | D21: Closed | E21: SRCO Legal / Salvador Raghav & Co. | F21: 8000 | G21: 0 | H21: 8000 | I21: B2B | K21: Total Result | L21: 47182229 | M21: 393125.36 | O21: 47575354
A22: 45627 | B22: 45657 | C22: INV-000045 | D22: Closed | E22: B2C | F22: 4990 | G22: 0 | H22: 4990 | I22: B2C
A23: 45658 | B23: 45658 | C23: INV-000046 | D23: Closed | E23: Agama Law Associates | F23: 80000 | G23: 0 | H23: 80000 | I23: B2B
A24: 45658 | B24: 45662 | C24: INV-000047 | D24: Closed | E24: B2C | F24: 6780 | G24: 0 | H24: 6780 | I24: B2C
A25: 45658 | B25: 45662 | C25: INV-000048 | D25: Closed | E25: Gourab Banerji | F25: 49998 | G25: 0 | H25: 49998 | I25: B2B
A26: 45658 | B26: 45665 | C26: INV-000049 | D26: Closed | E26: B2C | F26: 1691 | G26: 0 | H26: 1691 | I26: B2C
A27: 45658 | B27: 45665 | C27: INV-000050 | D27: Closed | E27: Parakram Legal | F27: 5000 | G27: 0 | H27: 5000 | I27: B2B
A28: 45658 | B28: 45666 | C28: INV-000051 | D28: Closed | E28: Kanungo & Co. | F28: 3999 | G28: 0 | H28: 3999 | I28: B2B
A29: 45658 | B29: 45668 | C29: INV-000052 | D29: Closed | E29: B2C | F29: 4487 | G29: 0 | H29: 4487 | I29: B2C
A30: 45658 | B30: 45668 | C30: INV-000053 | D30: Closed | E30: Diwan Law Associates | F30: 5000 | G30: 0 | H30: 5000 | I30: B2B
A31: 45658 | B31: 45671 | C31: INV-000054 | D31: Closed | E31: B2C | F31: 1889 | G31: 0 | H31: 1889 | I31: B2C
A32: 45658 | B32: 45671 | C32: INV-000055 | D32: Closed | E32: Mustafa S. Doctor | F32: 162000 | G32: 0 | H32: 162000 | I32: B2B
A33: 45658 | B33: 45674 | C33: INV-000056 | D33: Closed | E33: B2C | F33: 5683 | G33: 0 | H33: 5683 | I33: B2C
... A308: 45597 | B308: 45626 | C308: INV-000026 | D308: Closed | E308: B2C | F308: 2293 | G308: 0 | H308: 2293 | I308: B2C
A309: 45809 | B309: 45809 | C309: INV-25-26-000161 | D309: Overdue | E309: LEGALOGIC CONSULTING LLP | F309: 38000 | G309: 6840 | H309: =F309+G309 -> 44840 | I309: B2B | J309: =VLOOKUP(C309,'FY 25-26-Accrual'!$D$192:$D$233,1,0) -> INV-25-26-000161
A310: 45809 | B310: 45810 | C310: INV-25-26-000162 | D310: Closed | E310: B2C | F310: 6772.88 | G310: 1219.1184 | H310: =F310+G310 -> 7991.9984 | I310: B2C | J310: =VLOOKUP(C310,'FY 25-26-Accrual'!$D$192:$D$233,1,0) -> #N/A
A311: 45809 | B311: 45810 | C311: INV-25-26-000163 | D311: Closed | E311: Poovayya & CO | F311: 20000 | G311: 3600 | H311: =F311+G311 -> 23600 | I311: B2B | J311: =VLOOKUP(C311,'FY 25-26-Accrual'!$D$192:$D$233,1,0) -> INV-25-26-000163
A312: 45809 | B312: 45810 | C312: INV-25-26-000164 | D312: Closed | E312: Sajan Poovayya | F312: 20000 | G312: 3600 | H312: =F312+G312 -> 23600 | I312: B2B | J312: =VLOOKUP(C312,'FY 25-26-Accrual'!$D$192:$D$233,1,0) -> INV-25-26-000164
A313: 45809 | B313: 45811 | C313: INV-25-26-000165 | D313: Overdue | E313: Shrey Lodha | F313: 10000 | G313: 1800 | H313: =F313+G313 -> 11800 | I313: B2B | J313: ='FY 25-26-Accrual'!$D$234 -> INV-25-26-000165 & CN-00011
A314: 45809 | B314: 45812 | C314: INV-25-26-000166 | D314: Closed | E314: Gupta Law Associates | F314: 15000 | G314: 2700 | H314: =F314+G314 -> 17700 | I314: B2B | J314: =VLOOKUP(C314,'FY 25-26-Accrual'!$D$192:$D$233,1,0) -> INV-25-26-000166
A315: 45809 | B315: 45812 | C315: INV-25-26-000167 | D315: Overdue | E315: Vardharma Chambers | F315: 7000 | G315: 1260 | H315: =F315+G315 -> 8260 | I315: B2B | J315: =VLOOKUP(C315,'FY 25-26-Accrual'!$D$192:$D$233,1,0) -> INV-25-26-000167
...

Sheet Active Subscriber
A1: 45627 | D1: 45658 | G1: Feb | J1: Mar | M1: 45748 | P1: May | S1: June | U1: July | X1: 45870 | AA1: Sept | AD1: Oct
A2: The Guild | Advocates & Associate Counsel | B2: =VLOOKUP(A2,D:D,1,0) -> The Guild | Advocates & Associate Counsel | D2: Shyam Kapadia | E2: =VLOOKUP(D2,G:G,1,0) -> Shyam Kapadia | G2: The Guild | Advocates & Associate Counsel | H2: =VLOOKUP(G2,J:J,1,0) -> The Guild | Advocates & Associate Counsel | J2: The Guild | Advocates & Associate Counsel | K2: =VLOOKUP(J2,M:M,1,0) -> The Guild | Advocates & Associate Counsel | M2: Touchstone Partners | N2: =VLOOKUP(M2,P:P,1,0) -> Touchstone Partners | P2: Touchstone Partners | Q2: =VLOOKUP(P2,S:S,1,0) -> Touchstone Partners | S2: Touchstone Partners | T2: =VLOOKUP(S2,U:U,1,0) -> #N/A | U2: Veritas Legal Advocates and Solicitors | V2: =VLOOKUP(U2,X:X,1,0) -> Veritas Legal Advocates and Solicitors | X2: The Guild | Advocates & Associate Counsel | Y2: =VLOOKUP(X2,AA:AA,1,0) -> The Guild | Advocates & Associate Counsel | AA2: Veritas Legal Advocates and Solicitors | AB2: =VLOOKUP(AA2,AD:AD,1,0) -> Veritas Legal Advocates and Solicitors | AD2: Veritas Legal Advocates and Solicitors | AE2: =VLOOKUP(AD2,AA:AA,1,0) -> Veritas Legal Advocates and Solicitors
